Workbook
Name LU_Worksheet_1145076_18147: lookuplists!$A$1:$A$10
Name LU_Worksheet_1145076_18243: lookuplists!$B$1:$B$3
Name LU_Worksheet_1145076_18259: lookuplists!$C$1:$C$5

Sheet Client Input
B1: Radford McLagan Compensation Database (2024)
B2: Client Input
B3: We require all participants to provide the following information to enable dynamic data filtering and data validation. Where possible we have populated values previously provided to Aon in prior cycles or via a public source. We recommend reviewing and modifying to provide us with the most accurate information.
B5: Client Information (required for all participanting clients)
B6: Data Element Name | C6: Description | D6: Enter/Select Values
A7: PartName | B7: Client Name | C7: Enter the name of the participating organization. | D7: Grafana Labs
A8: PartLevel | B8: Client Level | C8: Select to indicate whether the participating organization represents the entire company or a sub-set of the company. If participant is a Subsidiary, select Multi-Profit or Group: ▪ Corporate - the entire company ▪ Multi-Profit or Group - a geographic region or global business line ▪ Single-Profit or Division - a single location or single business line ▪ Plant - a manufacturing cost center | D8: Corporate
A9: PFirmName | B9: Parent Company Name | C9: Enter parent company name when the 'Client Level' above is not 'Corporate'.
A10: PartCntry | B10: Client Location | C10: Select the headquarters location for the participating client. | D10: US
A11: PartCity | B11: Client City | C11: Enter the headquarters city for the participating client. | D11: New York
A12: PartState | B12: Client State | C12: For US headquartered clients, enter the headquarters state for the participating client. | D12: NY
A13: PartOwnshp | B13: Client Ownership | C13: Select the client's ownership type: ▪ Public ▪ Private: Venture Backed ▪ Private: Private Equity - Growth ▪ Private: Private Equity - Buyout ▪ Private: Other ▪ Not-For-Profit ▪ Government / State-Owned Enterprise | D13: Private: Venture Backed
A14: PartSub | B14: Subsidiary | C14: Select "Yes" to identify if the participating client is a subsidiary of a parent company: ▪ Yes
A15: PartInds | B15: Client Industry | C15: Select one of the standardized RMCD Industries that best represents your organization. See the Industry Definitions tab for detailed industry definitions. | D15: TS01 - Software Products/Services
B16: Client Industry Definition | C16: For reference only, the following represents the definition of the industry selected above. See the Industry Definitions tab for detailed industry definitions. | D16: =IFERROR(INDEX('Industry Definitions'!D6:D163,MATCH(D15,'Industry Definitions'!C6:C163,0)),"") -> Developers and producers of software products such as application software (downloadable or pre-packaged software products) for businesses or consumers, data security/data hosting, middleware/firmware and systems software. NOT companies creating apps to conduct their business (which fits another industry). Developers/creators of entertainment/gaming software - use Gaming/Multi-media (GE01).
A17: PartDesc | B17: Business Description | C17: Enter a high-level description of the participating client's primary product or service area (less than 50 characters). For energy utility companies only (electricity, natural gas, water), please also indicate whether the business operates as Regulated, Deregulated/Nonregulated, or Both (Regulated and Deregulated/Nonregulated). | D17: SaaS, Observability & Monitoring, Metrics
A18: PartLYRev | B18: Client Revenue Last Fiscal Year | C18: Enter the participating client's annual revenue from the last fiscal year in United States Dollars. Please reference the "Currencies" tab to convert the data from other currencies.
A19: PartHCount | B19: Total Headcount | C19: Enter the participating client's total number of employees at the time of submission.
B21: Additional Client Information (required if applicable)
B22: Data Element Name | C22: Description | D22: Enter/Select Values
A23: SalesChan | B23: Primary Sales Channel | C23: Select the participating client's primary sales channel: ▪ Direct / End User - Directly to the end user of a product or service ▪ Government Direct - Directly to the Federal/National government ▪ Original Equipment Manufacturer (OEM) - Directly to original equipment manufacturers ▪ Value-Added Reseller (VAR) - Directly to value-added resellers or systems integrators ▪ Distribution - Directly to distributors/dealers/agents ▪ Retail - Directly to retailers ▪ E-Commerce - Through a website ▪ No Sales | D23: Direct / End User
A24: LSCmpnyTyp | B24: Life Sciences Company Type | C24: For Life Sciences clients only, select the company type: ▪ Brand ▪ Generic and/or Biosimilar ▪ Combination - Generic and/or Biosimilar/Brand ▪ Medical Device – Capital Equipment ▪ Medical Device – Diagnostic Devices & Tools ▪ Medical Device – Hospital Products ▪ Medical Device – Implantable Devices ▪ Institutions and Foundations ▪ Other
A25: StageDevpt | B25: Stage of Development | C25: For Life Sciences clients, select the current stage of development. ▪ Product Definition (Startup/Pre-Alpha/Discovery) - The earliest stage of development which includes proof of concept, and an analysis of requirements, design, development, and various forms of early testing. ▪ Product Development (R&D/Alpha) - The first phase of testing which includes many known and unknown issues. Includes Preclinical Research and Product Classification, and determining whether or not life sciences product(s) should be tested in humans. ▪ Product Testing (Early-Stage) - The second phase of testing, often known as Beta, which may include a low number of known issues. In life sciences products, includes Pre-Market Notification, clinical trials (Phase I and Phase II), and early feasibility research. ▪ Product Testing (Late-Stage) - The final step in testing which includes a release candidate, prior to the launch of a finished product. Includes Pre-Market Submission, clinical trials (Phase III and Phase IV), and pivotal and post market research. ▪ Shipping Product (Revenue Generating) - Shipping Product (Revenue Generating) ▪ Profitable - Profitable | D25: Shipping Product (Revenue Generating)
B27: Cap Table and Private Company Details – this section is mandatory for privately-held companies.
B28: Data Element Name | C28: Description | D28: Enter/Select Values
A29: YearFound | B29: Year Founded | C29: Enter the year in which the company was founded (YYYY). | D29: 2014
A30: LastFundRd | B30: Last Funding Round | C30: Select the company's Last Round of Funding (Angel, Seed, Series A, Series B, Series C, Series D, Series E, Series F or Later).
A31: InvRaiseCp | B31: Invested Capital / Capital Raised | C31: Enter the company's total amount of Invested Capital / Capital Raised. If subject to tranche investment, include paid-in tranches only. (Please enter in USD - Whole Number Only).
A32: MRCompVal | B32: Most Recent Company Valuation | C32: Enter the company's Most Recent Company Valuation based on the latest financing round.
A33: MRCommSSP | B33: Most Recent Common Stock Share Price | C33: Enter the company's most recent common stock share price.
A34: MRPrefSSP | B34: Most Recent Preferred Stock Share Price | C34: Enter the company's most recent preferred stock share price.
A35: EquityType | B35: Equity Vehicles Granted to Employees | C35: Select which equity vehicles are granted to employees (Stock Options, Restricted Stock Units, Restricted Stock Awards, Stock Options & Restricted Stock Awards, Stock Appreciation Rights, Warrants, Profit Interest Units, Capital Interest Units)
A36: FullDShare | B36: Fully Diluted Shares | C36: Enter the total number of fully diluted shares. This includes all issued, unissued, vested, and unvested shares.
A37: ComHeldAll | B37: Common Stock Held by All Employees | C37: For all employees (executives and staff) enter the total number of common stock equivalent shares owned. Ownership may be from the receipt of founder shares, the exercise of stock options, and/or the settlement of restricted stock.
A38: PrfHeldAll | B38: Preferred Stock Held by All Employees | C38: For all employees (executives and staff) enter the total number of preferred shares, stated in common stock equivalent shares. Ownership is typically a result of investment of personal funds to purchase preferred shares.
A39: UnxEqtyAll | B39: Unexercised Equity Awards Held by All Employees | C39: For All Employees (executives and staff) enter the total number of common stock equivalent shares, vested/unvested unexercised options or unvested restricted stock.
A40: UnxWrntAll | B40: Unexercised Warrants Held by All Employees | C40: For All Employees (executives and staff) enter the total number of warrants held. Warrants are a derivative security that gives the holder the right to purchase securities from the issuer at a specific price within a certain time frame.
A41: ComHeldNoE | B41: Common Stock Held by Non-Employees | C41: For Non-Employees (VC Firms, Board Members, Outside Investors & Former Employees) enter the total number of common stock equivalent shares owned. Ownership may be from the receipt of founder shares, the exercise of stock options, and/or the settlement of restricted stock.
... A45: ShareAvail | B45: Shares Available for Grant in Equity Plans (Unissued Shares) | C45: Enter the Shares Available for Grant in Equity Plans (Unissued Shares).
B46: Calculated Equity Check | C46: For reference only, should be 0, or close: | D46: =D36-SUM(D37:D45) -> 0
...

Sheet Firm Data
A1: PartName | B1: PartLevel | C1: PFirmName | D1: PartCntry | E1: PartCity | F1: PartState | G1: PartOwnshp | H1: PartSub | I1: PartInds | J1: PartDesc | K1: PartLYRev | L1: PartHCount | M1: SalesChan | N1: LSCmpnyTyp | O1: StageDevpt | P1: YearFound | Q1: LastFundRd | R1: InvRaiseCp | S1: MRCompVal | T1: MRCommSSP | U1: MRPrefSSP | V1: EquityType | W1: FullDShare | X1: ComHeldAll | Y1: PrfHeldAll | Z1: UnxEqtyAll | AA1: UnxWrntAll | AB1: ComHeldNoE | AC1: PrfHeldNoE | AD1: UnxEqtyNoE | AE1: UnxWrntNoE | AF1: ShareAvail | AG1: AsstUMgt | AH1: TotalAsset | AI1: CapIndpnt | AJ1: FundMgtSty | AK1: AMInvsProd | AL1: AMAltProd | AM1: INSDirPrem | AN1: ResLoanPrd
A2: Client Name | B2: Client Level | C2: Parent Company Name | D2: Client Location | E2: Client City | F2: Client State | G2: Client Ownership | H2: Subsidiary | I2: Client Industry | J2: Business Description | K2: Client Revenue Last Fiscal Year | L2: Total Headcount | M2: Primary Sales Channel | N2: Life Sciences Company Type | O2: Stage of Development | P2: Year Founded | Q2: Last Funding Round | R2: Invested Capital / Capital Raised | S2: Most Recent Company Valuation | T2: Most Recent Common Stock Share Price | U2: Most Recent Preferred Stock Share Price | V2: Equity Vehicles Granted to Employees | W2: Fully Diluted Shares | X2: Common Stock Held by All Employees | Y2: Preferred Stock Held by All Employees | Z2: Unexercised Equity Awards Held by All Employees | AA2: Unexercised Warrants Held by All Employees | AB2: Common Stock Held by Non-Employees | AC2: Preferred Stock Held by Non-Employees | AD2: Unexercised or Unearned Equity Awards Held by Non-Employees | AE2: Unexercised Warrants Held by Non-Employees | AF2: Shares Available for Grant in Equity Plans (Unissued Shares) | AG2: Assets Under Management | AH2: Total Assets | AI2: Fund's Management Style | AJ2: Captive / Independent | AK2: Principal Investment Product | AL2: Principal Alternative Product | AM2: Insurance Direct Written Premium | AN2: Residential Mortgage Loan Production
A3: =IFERROR('Client Input'!$D$7,"") -> Grafana Labs | B3: =IFERROR('Client Input'!$D$8,"") -> Corporate | C3: =IFERROR('Client Input'!$D$9,"") -> 0 | D3: =IFERROR('Client Input'!$D$10,"") -> US | E3: =IFERROR('Client Input'!$D$11,"") -> New York | F3: =IFERROR('Client Input'!$D$12,"") -> NY | G3: =IFERROR('Client Input'!$D$13,"") -> Private: Venture Backed | H3: =IFERROR('Client Input'!$D$14,"") -> 0 | I3: =IFERROR('Client Input'!$D$15,"") -> TS01 - Software Products/Services | J3: =IFERROR('Client Input'!$D$17,"") -> SaaS, Observability & Monitoring, Metrics | K3: =IFERROR('Client Input'!$D$18,"") -> 0 | L3: =IFERROR('Client Input'!$D$19,"") -> 0 | M3: =IFERROR('Client Input'!$D$23,"") -> Direct / End User | N3: =IFERROR('Client Input'!$D$24,"") -> 0 | O3: =IFERROR('Client Input'!$D$25,"") -> Shipping Product (Revenue Generating) | P3: =IFERROR('Client Input'!$D$29,"") -> 2014 | Q3: =IFERROR('Client Input'!$D$30,"") -> 0 | R3: =IFERROR('Client Input'!$D$31,"") -> 0 | S3: =IFERROR('Client Input'!$D$32,"") -> 0 | T3: =IFERROR('Client Input'!$D$33,"") -> 0 | U3: =IFERROR('Client Input'!$D$34,"") -> 0 | V3: =IFERROR('Client Input'!$D$35,"") -> 0 | W3: =IFERROR('Client Input'!$D$36,"") -> 0 | X3: =IFERROR('Client Input'!$D$37,"") -> 0 | Y3: =IFERROR('Client Input'!$D$38,"") -> 0 | Z3: =IFERROR('Client Input'!$D$39,"") -> 0 | AA3: =IFERROR('Client Input'!$D$40,"") -> 0 | AB3: =IFERROR('Client Input'!$D$41,"") -> 0 | AC3: =IFERROR('Client Input'!$D$42,"") -> 0 | AD3: =IFERROR('Client Input'!$D$43,"") -> 0 | AE3: =IFERROR('Client Input'!$D$44,"") -> 0 | AF3: =IFERROR('Client Input'!$D$45,"") -> 0 | AG3: =IFERROR('Client Input'!$D$50,"") -> 0 | AH3: =IFERROR('Client Input'!$D$51,"") -> 0 | AI3: =IFERROR('Client Input'!$D$52,"") -> 0 | AJ3: =IFERROR('Client Input'!$D$53,"") -> 0 | AK3: =IFERROR('Client Input'!$D$54,"") -> 0 | AL3: =IFERROR('Client Input'!$D$55,"") -> 0 | AM3: =IFERROR('Client Input'!$D$56,"") -> 0 | AN3: =IFERROR('Client Input'!$D$57,"") -> 0

Sheet Employee Input
B1: Radford McLagan Compensation Database (2024)
B2: Employee Input
B4: Unique Identity | D4: Key | I4: Job Attribute Codes | O4: Job Attribute Names | U4: Key | AE4: Executive | AL4: Currency | AM4: 2023 Compensation | CC4: 2024 Compensation | DK4: Additional | EZ4: Legacy Reference
B5: Client Code | C5: Employee Code | D5: Location / Area | F5: Postal Code | G5: City | H5: State | I5: Module Code | J5: Function Code | K5: Area Code | L5: Focus Code | M5: Level Code | N5: Job Code | O5: Module Name | P5: Function Name | Q5: Area Name | R5: Focus Name | S5: Level Name | T5: Job Title | U5: Employee Industry | V5: Business Unit Name | W5: Internal Job Title | X5: Internal Job Code | Y5: Manager Employee Code | Z5: Job Classification | AA5: Employment Status | AB5: Employee Status | AC5: Hire Date | AD5: Entry Into Current Role | AE5: Executive Revenue Responsibility | AF5: Executive Scope of Responsibility | AG5: Plant Headcount Responsibility | AH5: Executive Reporting Layer | AI5: Elected Officer | AJ5: Executive Geographic Responsibility | AK5: Founder | AL5: Compensation Currency | AM5: Last Fiscal Year Base Salary | AN5: Last Fiscal Year Monthly Pay | AO5: Last Fiscal Year Hourly Rate | AP5: Last Fiscal Year Minimum Hourly Rate | AQ5: Last Fiscal Year Maximum Hourly Rate | AR5: Last Fiscal Year Retirals | AS5: Last Fiscal Year Other Retirals | AT5: Last Fiscal Year Gratuity | AU5: Last Fiscal Year Cash Incentives Eligibility | AV5: Last Fiscal Year Cash Incentives Received | AW5: Last Fiscal Year Cash Incentives | AX5: Last Fiscal Year FS Commission | AY5: Last Fiscal Year Target Cash Incentives | AZ5: Last Fiscal Year Overtime | BA5: Last Fiscal Year Participation & Intéressement Award | BB5: Last Fiscal Year Bonus / Ex Gratia Amount | BC5: Last Fiscal Year Broker Paid Bonus | BD5: Last Fiscal Year Car Allowance | BE5: Last Fiscal Year Transportation Allowance | BF5: Last Fiscal Year Meal Allowance | BG5: Last Fiscal Year National Allowance | BH5: Last Fiscal Year Dearness Allowance | BI5: Last Fiscal Year Housing and Rent Allowance | BJ5: Last Fiscal Year Role-Based Allowance | BK5: Last Fiscal Year Site Allowance | BL5: Last Fiscal Year Shift Allowance | BM5: Last Fiscal Year Other Allowances | BN5: Equity Grant Currency | BO5: Last Fiscal Year Long-Term Incentives Eligibility | BP5: Last Fiscal Year Options / Stock Appreciation Rights Number of Shares | BQ5: Last Fiscal Year Options / Stock Appreciation Rights Share Price | BR5: Last Fiscal Year Restricted Stock Number of Shares | BS5: Last Fiscal Year Restricted Stock Share Price | BT5: Last Fiscal Year Performance Shares Target Number of Shares | BU5: Last Fiscal Year Performance Share Price | BV5: Last Fiscal Year Deferred Cash | BW5: Last Fiscal Year Long-Term Cash Incentive Grant Target Amount | BX5: Last Fiscal Year Other Long-Term Incentives | BY5: Last Fiscal Year Personal Number of Loans | BZ5: Last Fiscal Year Personal Production | CA5: Spot Recognition Awards | CB5: Total Billings | CC5: Current Fiscal Year Base Salary | CD5: Current Fiscal Year Monthly Pay | CE5: Current Fiscal Year Hourly Rate | CF5: Current Fiscal Year Minimum Hourly Rate | CG5: Current Fiscal Year Maximum Hourly Rate | CH5: Current Fiscal Year Cash Incentives Eligibility | CI5: Current Fiscal Year Target Cash Incentives | CJ5: Current Fiscal Year New Hire Cash Incentive | CK5: Current Fiscal Year Maximum Cash Incentives | CL5: Current Fiscal Year Retirals | CM5: Current Fiscal Year Other Retirals | CN5: Current Fiscal Year Gratuity | CO5: Internal Salary Grade | CP5: Internal Hourly Salary Grade Midpoint | CQ5: Internal Base Salary Grade Midpoint | CR5: Current Fiscal Year Car Allowance | CS5: Current Fiscal Year Car Allowance Received | CT5: Current Fiscal Year Transportation Allowance | CU5: Current Fiscal Year Meal Allowance | CV5: Current Fiscal Year National Allowance | CW5: Current Fiscal Year Dearness Allowance | CX5: Current Fiscal Year Housing and Rent Allowance | CY5: Current Fiscal Year Role-Based Allowance | CZ5: Current Fiscal Year Site Allowance | DA5: Current Fiscal Year Shift Allowance | DB5: Current Fiscal Year Other Allowances | DC5: New-Hire Long-Term Incentives Eligibility | DD5: Current Fiscal Year New-Hire Options / Stock Appreciation Rights Number of Shares | DE5: Current Fiscal Year New-Hire Options / Stock Appreciation Rights Share Price | DF5: Current Fiscal Year New-Hire Restricted Stock Number of Shares | DG5: Current Fiscal Year New-Hire Restricted Stock Share Price | DH5: Current Fiscal Year New-Hire Performance Shares Target Number of Shares | DI5: Current Fiscal Year New-Hire Performance Share Price | DJ5: Current Fiscal Year New-Hire Long-Term Cash Incentive Grant Amount | DK5: New-Hire Stock Received Last 12 Months | DL5: Shares Held & Unexercised Options | DM5: Last Fiscal Year Quota or Target Sales Volume | DN5: Last Fiscal Year Actual Sales Volume | DO5: Last Fiscal Year Quota/Actual Sales Volume Quota Modifier | DP5: Current Fiscal Year Quota Modifier | DQ5: Current Fiscal Year Quota or Target Sales Volume | DR5: Investment Banking Lockstep | DS5: Manager or Professional Indicator | DT5: Consulting Client Industry Focus | DU5: Solutions Technical Alignment | DV5: New Hire Detail | DW5: Life Sciences Product Alignment | DX5: Restaurant Concept Type Alignment | DY5: Energy & Mining Specialty /Commodities Alignment | DZ5: Mining Residential Type | EA5: Mining Work Environment & Work Pattern | EB5: Energy & Mining General Roster Pattern | EC5: Energy Offshore Type | ED5: Year of Birth | EE5: Gender | EF5: Ethnicity | EG5: Highest Degree Earned | EH5: Year Highest Degree Earned | EI5: New University Graduate | EJ5: Weekly Hours | EK5: Full Time Equivalent (%) | EL5: Worker Location Type | EM5: Performance Rating | EN5: Financial Services Corporate Title | EO5: Desk Manager Identifier | EP5: Consulting Billable Hours | EQ5: Wealth Management Client Segment | ER5: Wealth Management On-/Off-Shore Indicator | ES5: Wealth Management Client Geographic Focus | ET5: Financial Services Regulatory Designation | EU5: Financial Technology Business Alignment | EV5: Insurance Business Alignment | EW5: Investor Services Business Alignment | EX5: Private Equity Carried Interest Participant | EY5: Enterprise Bargaining Agreement/Award | EZ5: Legacy McLagan Client Code | FA5: Legacy Radford Client Code | FB5: 2023 Survey Code | FC5: 2023 Job Code | FD5: 2023 Survey Name | FE5: 2023 Job Name
B6: FirmCode | C6: EmpCode | D6: WorkCntry | F6: PostCode | G6: WorkCity | H6: WorkState | I6: SUBGROUP | J6: FUNCTION | K6: AREA | L6: FOCUS | M6: LEVEL | N6: JobCode | O6: SUBGRP_NM | P6: FUNC_NM | Q6: AREA_NM | R6: FOCUS_NM | S6: LEVEL_NM | T6: JobTitle | U6: EmpInds | V6: EXBusUnit | W6: IntJobTitl | X6: IntJobCode | Y6: MgrEmpCode | Z6: JobClass | AA6: EmpStatus | AB6: PayStatus | AC6: HireDate | AD6: EntCurRole | AE6: EXRevResp | AF6: EXScopeRes | AG6: EXPlantHC | AH6: EXRepLayer | AI6: EXElectOff | AJ6: EXGeoRes | AK6: Founder | AL6: CurrCode | AM6: LYBaseSal | AN6: LYMonPay | AO6: LYHourRate | AP6: LYMinHour | AQ6: LYMaxHour | AR6: LYRetirals | AS6: LYOtherRet | AT6: LYGratuity | AU6: LYCashElig | AV6: LYCashRec | AW6: LYCashInc | AX6: LYFSCom | AY6: LYTCashInc | AZ6: LYOvertime | BA6: LYPartInt | BB6: LYBonxGrat | BC6: LYBrokrBon | BD6: LYCarAllow | BE6: LYTranAllw | BF6: LYMealAllw | BG6: LYNatAllow | BH6: LYDearAllw | BI6: LYHouseRnt | BJ6: LYRoleAllw | BK6: LYSiteAllw | BL6: LYShifAllw | BM6: LYOthrAllw | BN6: EquityPric CurrCode | BO6: ONLTIElig | BP6: ONOPNumShr | BQ6: ONOPShrPri | BR6: ONRSNumShr | BS6: ONRSShrPri | BT6: ONPSNumShr | BU6: ONPSShrPri | BV6: LYDefCash | BW6: ONCITarAmt | BX6: LYOthLonIn | BY6: LYPNLoans | BZ6: LYPerProd | CA6: SpotRecAwd | CB6: TotBilling | CC6: CYBaseSal | CD6: CYMonPay | CE6: CYHourRate | CF6: CYMinHour | CG6: CYMaxHour | CH6: CYCashElig | CI6: CYTCashInc | CJ6: NHCashBon | CK6: CYMaxBonus | CL6: CYRetirals | CM6: CYOtherRet | CN6: CYGratuity | CO6: SalGrade | CP6: HourSalGrd | CQ6: SalGradMid | CR6: CYCarAllow | CS6: CYCarAlRec | CT6: CYTranAllw | CU6: CYMealAllw | CV6: CYNatAllow | CW6: CYDearAllw | CX6: CYHouseRnt | CY6: CYRoleAllw | CZ6: CYSiteAllw | DA6: CYShifAllw | DB6: CYOthrAllw | DC6: NHLTIElig | DD6: NHOPNumShr | DE6: NHOPShrPri | DF6: NHRSNumShr | DG6: NHRSShrPri | DH6: NHPSNumShr | DI6: NHPSShrPri | DJ6: NHCITarAmt | DK6: NHStockAmt | DL6: SharesHeld | DM6: LYQuoTSV | DN6: LYQuoASV | DO6: LYQuoMod | DP6: CYQuoMod | DQ6: CYQuoTSV | DR6: IBLockstep | DS6: MgrProfInd | DT6: CNBusAlign | DU6: SolTechAli | DV6: NHDetail | DW6: LSProduct | DX6: RestConcpt | DY6: EnergySpec | DZ6: MinResType | EA6: MinWrkEnPT | EB6: EnMinRoPat | EC6: EnrgyOff | ED6: YearBirth | EE6: Gender | EF6: Ethnicity | EG6: HiDegEar | EH6: HiDegEarYr | EI6: NewGrad | EJ6: WeekHour | EK6: FTEquiv | EL6: WorkLocTyp | EM6: PerfRating | EN6: FSCorpTitl | EO6: DeskMgr | EP6: BilledHour | EQ6: WMClintSeg | ER6: WMOnOff | ES6: WMGeoFocus | ET6: FSRegDes | EU6: FTBusAlign | EV6: INBusAlign | EW6: ISBusAlign | EX6: PECarryInt | EY6: EntBargAgr | EZ6: Mcl_LgcyFC | FA6: Rwd_LgcyFC | FB6: LGYSURCODE | FC6: LGYJOB | FD6: LGYSURNAM | FE6: LGYJOBNAME
